Workbook

Sheet Summering
B1: SE 4 | G1: 2023 | I1: 2023
C2: BV | D2: hus 1 | E2: nej | G2: ='SE4'!P26 -> 2800.0139 | I2: 2310.2938
E3: sol | G3: ='SE4'!P27 -> 4770.0479 | I3: 4360.262
E4: elbil | G4: ='SE4'!P28 -> 3096.0139 | I4: 2482.9604
E5: sol+elbil | G5: ='SE4'!P29 -> 5066.0479 | I5: 4532.9287
D6: hus 2 | E6: nej | G6: ='SE4'!P30 -> 3877.7963 | I6: 3054.4672
E7: sol | G7: ='SE4'!P31 -> 5847.8303 | I7: 5104.4354
E8: elbil | G8: ='SE4'!P32 -> 4315.7963 | I8: 3309.9672
E9: sol+elbil | G9: ='SE4'!P33 -> 6285.8303 | I9: 5359.9354
D10: hus 3 | E10: nej | G10: ='SE4'!P34 -> 5168.5114 | I10: 4424.5875
E11: sol | G11: ='SE4'!P35 -> 7138.5454 | I11: 6474.5557
E12: elbil | G12: ='SE4'!P36 -> 5680.5114 | I12: 4723.2542
E13: sol+elbil | G13: ='SE4'!P37 -> 7650.5454 | I13: 6773.2224
D14: hus 4 | E14: nej | G14: ='SE4'!P38 -> 7254.7844 | I14: 6421.4901
E15: sol | G15: ='SE4'!P39 -> 9224.8184 | I15: 8471.4584
E16: elbil | G16: ='SE4'!P40 -> 7988.7844 | I16: 6849.6568
E17: sol+elbil | G17: ='SE4'!P41 -> 9958.8184 | I17: 8899.625
C18: LV | D18: hus 1 | E18: nej | G18: ='SE4'!P42 -> 3686.0796 | I18: 2873.1672
E19: sol | G19: ='SE4'!P43 -> 5656.1136 | I19: 4923.1354
E20: elbil | G20: ='SE4'!P44 -> 4050.0796 | I20: 3085.5005
E21: sol+elbil | G21: ='SE4'!P45 -> 6020.1136 | I21: 5135.4688
D22: hus 2 | E22: nej | G22: ='SE4'!P46 -> 4723.862 | I22: 3786.0773
E23: sol | G23: ='SE4'!P47 -> 6693.896 | I23: 5836.0456
E24: elbil | G24: ='SE4'!P48 -> 5217.862 | I24: 4074.244
E25: sol+elbil | G25: ='SE4'!P49 -> 7187.896 | I25: 6124.2123
D26: hus 3 | E26: nej | G26: ='SE4'!P50 -> 6917.6134 | I26: 6235.0813
E27: sol | G27: ='SE4'!P51 -> 8887.6474 | I27: 8285.0495
E28: elbil | G28: ='SE4'!P52 -> 7521.6134 | I28: 6587.4146
E29: sol+elbil | G29: ='SE4'!P53 -> 9491.6474 | I29: 8637.3828
D30: hus 4 | E30: nej | G30: ='SE4'!P54 -> 8655.199 | I30: 8422.4573
E31: sol | G31: ='SE4'!P55 -> 10625.233 | I31: 10472.426
E32: elbil | G32: ='SE4'!P56 -> 9397.199 | I32: 8855.2906
E33: sol+elbil | G33: ='SE4'!P57 -> 11367.233 | I33: 10905.259
C34: FL | D34: hus 1 | E34: nej | G34: ='SE4'!P58 -> 4610.3283 | I34: 3607.1229
E35: sol | G35: ='SE4'!P59 -> 6580.3623 | I35: 5657.0912
E36: elbil | G36: ='SE4'!P60 -> 5004.3283 | I36: 3836.9563
E37: sol+elbil | G37: ='SE4'!P61 -> 6974.3623 | I37: 5886.9245
D38: hus 2 | E38: nej | G38: ='SE4'!P62 -> 6602.2593 | I38: 5657.5078
E39: sol | G39: ='SE4'!P63 -> 8572.2933 | I39: 7707.4761
E40: elbil | G40: ='SE4'!P64 -> 7132.2593 | I40: 5966.6745
...

Sheet SE4
B1: VP-typ | C1: Hustyp | D1: Definition hustyper | E1: Antal kvm | F1: ålder | G1: Kwh/kvm/år | H1: Förbrukning värme+vv, kWh | I1: Total förbrukning (+ hhel) | K1: SPO 2023 energikostnad, besparing | M1: SPO 2024 energikostnad, besparing | P1: Effekttariffer besparing per år
I2: 6500 | K2: Lägre elinköp %: | L2: 0.26 | M2: Lägre elinköp %: | N2: 0.25 | P2: utan elbil | Q2: inkl elbil
K3: utan styrning | L3: besparing styrning | M3: utan styrning | N3: besparing styrning | S3: Teckenförklaring
B4: MV | C4: Hus 1 | D4: 1 plans 100 kvm, 6 kW avgiven effekt | E4: 120 | F4: 1990 | G4: 55 | H4: =E4*G4 -> 6600 | I4: =H4+I$2 -> 13100 | K4: =H4/100*U$33 -> 6974.4125 | L4: =H4/100*U$33*L$2 -> 1813.3473 | M4: =H4/100*W$33 -> 5527.775 | N4: =H4/100*W$33*N$2 -> 1381.9438 | P4: =$Z33*$Z$35*12*((60-$Z$36)/60) -> 986.66667 | Q4: =$Z33*$Z$35*12*((60-$Z$37)/60) -> 1282.6667 | S4: Ändra parametrar här, testa (gul)
C5: Hus 2 | D5: 1-plan villa 150 kvm, 8 kW avgiven effekt | E5: 160 | F5: 2010 | G5: 55 | H5: =E5*G5 -> 8800 | I5: =H5+I$2 -> 15300 | K5: =H5/100*U$33 -> 9299.2167 | L5: =H5/100*U$33*L$2 -> 2417.7963 | M5: =H5/100*W$33 -> 7370.3667 | N5: =H5/100*W$33*N$2 -> 1842.5917 | P5: =AA33*Z$35*12*((60-Z$36)/60) -> 1460 | Q5: =$AA33*$Z$35*12*((60-$Z$37)/60) -> 1898 | S5: SPO-rasultat, tabell underlag
C6: Hus 3 | D6: 1,5 plan villa 200 kvm, 10 kW avgiven effekt | E6: 210 | F6: 1960 | G6: 60 | H6: =E6*G6 -> 12600 | I6: =H6+I$2 -> 19100 | K6: =H6/100*U$33 -> 13314.788 | L6: =H6/100*U$33*L$2 -> 3461.8448 | M6: =H6/100*W$33 -> 10553.025 | N6: =H6/100*W$33*N$2 -> 2638.2563 | P6: =AB33*Z$35*12*((60-Z$36)/60) -> 1706.6667 | Q6: =$AB33*$Z$35*12*((60-$Z$37)/60) -> 2218.6667 | S6: SOL-resultat & beräkning
C7: Hus 4 | D7: 2-plan villa 250 kvm+, 14 kW avgiven effekt | E7: 250 | F7: 1970 | G7: 70 | H7: =E7*G7 -> 17500 | I7: =H7+I$2 -> 24000 | K7: =H7/100*U$33 -> 18492.76 | L7: =H7/100*U$33*L$2 -> 4808.1177 | M7: =H7/100*W$33 -> 14656.979 | N7: =H7/100*W$33*N$2 -> 3664.2448 | P7: =AC33*Z$35*12*((60-Z$36)/60) -> 2446.6667 | Q7: =$AC33*$Z$35*12*((60-$Z$37)/60) -> 3180.6667 | S7: Tariffer-resultat & beräkning
B8: LV | C8: Hus 1 | E8: 120 | G8: 75 | H8: =E8*G8 -> 9000 | I8: =H8+I$2 -> 15500 | K8: =H8/100*U$33 -> 9510.5625 | L8: =H8/100*U$33*L$2 -> 2472.7463 | M8: =H8/100*W$33 -> 7537.875 | N8: =H8/100*W$33*N$2 -> 1884.4688 | P8: =$AD33*$Z$35*12*((60-$Z$36)/60) -> 1213.3333 | Q8: =$AD33*$Z$35*12*((60-$Z$37)/60) -> 1577.3333 | S8: Resultat besparing
C9: Hus 2 | E9: 160 | G9: 70 | H9: =E9*G9 -> 11200 | I9: =H9+I$2 -> 17700 | K9: =H9/100*U$33 -> 11835.367 | L9: =H9/100*U$33*L$2 -> 3077.1953 | M9: =H9/100*W$33 -> 9380.4667 | N9: =H9/100*W$33*N$2 -> 2345.1167 | P9: =$AE33*$Z$35*12*((60-$Z$36)/60) -> 1646.6667 | Q9: =$AE33*$Z$35*12*((60-$Z$37)/60) -> 2140.6667
C10: Hus 3 | E10: 210 | G10: 85 | H10: =E10*G10 -> 17850 | I10: =H10+I$2 -> 24350 | K10: =H10/100*U$33 -> 18862.616 | L10: =H10/100*U$33*L$2 -> 4904.2801 | M10: =H10/100*W$33 -> 14950.119 | N10: =H10/100*W$33*N$2 -> 3737.5297 | P10: =$AF33*$Z$35*12*((60-$Z$36)/60) -> 2013.3333 | Q10: =$AF33*$Z$35*12*((60-$Z$37)/60) -> 2617.3333
C11: Hus 4 | E11: 250 | G11: 90 | H11: =E11*G11 -> 22500 | I11: =H11+I$2 -> 29000 | K11: =H11/100*U$33 -> 23776.406 | L11: =H11/100*U$33*L$2 -> 6181.8656 | M11: =H11/100*W$33 -> 18844.688 | N11: =H11/100*W$33*N$2 -> 4711.1719 | P11: =$AG33*$Z$35*12*((60-$Z$36)/60) -> 2473.3333 | Q11: =$AG33*$Z$35*12*((60-$Z$37)/60) -> 3215.3333
B12: FL | C12: Hus 1 | E12: 120 | G12: 100 | H12: =E12*G12 -> 12000 | I12: =H12+I$2 -> 18500 | K12: =H12/100*U$33 -> 12680.75 | L12: =H12/100*U$33*L$2 -> 3296.995 | M12: =H12/100*W$33 -> 10050.5 | N12: =H12/100*W$33*N$2 -> 2512.625 | P12: =$AH33*$Z$35*12*((60-$Z$36)/60) -> 1313.3333 | Q12: =$AH33*$Z$35*12*((60-$Z$37)/60) -> 1707.3333
C13: Hus 2 | E13: 160 | G13: 110 | H13: =E13*G13 -> 17600 | I13: =H13+I$2 -> 24100 | K13: =H13/100*U$33 -> 18598.433 | L13: =H13/100*U$33*L$2 -> 4835.5927 | M13: =H13/100*W$33 -> 14740.733 | N13: =H13/100*W$33*N$2 -> 3685.1833 | P13: =$AI33*$Z$35*12*((60-$Z$36)/60) -> 1766.6667 | Q13: =$AI33*$Z$35*12*((60-$Z$37)/60) -> 2296.6667
C14: Hus 3 | E14: 210 | G14: 120 | H14: =E14*G14 -> 25200 | I14: =H14+I$2 -> 31700 | K14: =H14/100*U$33 -> 26629.575 | L14: =H14/100*U$33*L$2 -> 6923.6895 | M14: =H14/100*W$33 -> 21106.05 | N14: =H14/100*W$33*N$2 -> 5276.5125 | P14: =$AJ33*$Z$35*12*((60-$Z$36)/60) -> 2206.6667 | Q14: =$AJ33*$Z$35*12*((60-$Z$37)/60) -> 2868.6667
C15: Hus 4 | E15: 250 | G15: 130 | H15: =E15*G15 -> 32500 | I15: =H15+I$2 -> 39000 | K15: =H15/100*U$33 -> 34343.698 | L15: =H15/100*U$33*L$2 -> 8929.3615 | M15: =H15/100*W$33 -> 27220.104 | N15: =H15/100*W$33*N$2 -> 6805.026 | P15: =$AH33*$Z$35*12*((60-$Z$36)/60) -> 1313.3333 | Q15: =$AK33*$Z$35*12*((60-$Z$37)/60) -> 4064.6667
K17: Sol 2023 egenanvändning före/efter | M17: Sol 2024 energikostnad, besparing
K19: 0.3 | L19: 0.46 | M19: 0.3 | N19: 0.48 | S19: Elpriser tabell | T19: 2023 | V19: 2024 | Y19: Effekttabell tariffer | Z19: MV tillgänglig effekt | AD19: LV tillgänglig effekt | AH19: FL tillgänglig effekt
B20: Sol | C20: SE4 | D20: 25 paneler med 400 Wp | E20: 25 | G20: 400 | H20: =E20*G20 -> 10000 | K20: =H20*K$19*((U$35+U$37)*U$36)/100 -> 3693.8137 | L20: =(H20*L$19*((U$35+U$37)*U$36)/100)-(H20*K$19*((U$35+U$37)*U$36)/100) -> 1970.034 | M20: =H20*M$19*((W$35+W$37)*W$36)/100 -> 3313.9012 | N20: =(H20*N$19*((W$35+W$37)*W$36)/100)-(H20*M$19*((W$35+W$37)*W$36)/100) -> 1988.3407 | T20: el, exkl moms | U20: el, inkl moms+påslag | V20: exkl moms | W20: inkl moms+påslag | Z20: Hus 1 | AA20: Hus 2 | AB20: Hus 3 | AC20: Hus 4 | AD20: Hus 1 | AE20: Hus 2 | AF20: Hus 3 | AG20: Hus 4 | AH20: Hus 1 | AI20: Hus 2 | AJ20: Hus 3 | AK20: Hus 4
C21: SE3 | D21: 25 paneler med 400 Wp | E21: 25 | G21: 380 | H21: =E21*G21 -> 9500 | K21: =H21*K$19*((U$35+U$37)*U$36)/100 -> 3509.1231 | L21: =(H21*L$19*((U$35+U$37)*U$36)/100)-(H21*K$19*((U$35+U$37)*U$36)/100) -> 1871.5323 | M21: =H21*M$19*((W$35+W$37)*W$36)/100 -> 3148.2062 | N21: =(H21*N$19*((W$35+W$37)*W$36)/100)-(H21*M$19*((W$35+W$37)*W$36)/100) -> 1888.9237 | S21: jan | T21: 104.43 | U21: =(T21+10)*1.25 -> 143.0375 | V21: 84.02 | W21: =(V21+10)*1.25 -> 117.525 | Y21: jan | Z21: 1.7 | AA21: 2.4 | AB21: 3 | AC21: 4.2 | AD21: 2.3 | AE21: 3 | AF21: 3.7 | AG21: 4.8 | AH21: 3 | AI21: 4 | AJ21: 5.5 | AK21: 8
C22: SE2 | D22: 25 paneler med 400 Wp | E22: 25 | G22: 340 | H22: =E22*G22 -> 8500 | K22: =H22*K$19*((U$35+U$37)*U$36)/100 -> 3139.7417 | L22: =(H22*L$19*((U$35+U$37)*U$36)/100)-(H22*K$19*((U$35+U$37)*U$36)/100) -> 1674.5289 | M22: =H22*M$19*((W$35+W$37)*W$36)/100 -> 2816.8161 | N22: =(H22*N$19*((W$35+W$37)*W$36)/100)-(H22*M$19*((W$35+W$37)*W$36)/100) -> 1690.0896 | S22: feb | T22: 102.79 | U22: =(T22+10)*1.25 -> 140.9875 | V22: 55.42 | W22: =(V22+10)*1.25 -> 81.775 | Y22: feb | Z22: 1.7 | AA22: 2.4 | AB22: 3 | AC22: 4.2 | AD22: 2.5 | AE22: 3 | AF22: 3.7 | AG22: 4.8 | AH22: 3 | AI22: 4 | AJ22: 5.5 | AK22: 8
C23: SE1 | D23: 25 paneler med 400 Wp | E23: 25 | G23: 320 | H23: =E23*G23 -> 8000 | K23: =H23*K$19*((U$35+U$37)*U$36)/100 -> 2955.051 | L23: =(H23*L$19*((U$35+U$37)*U$36)/100)-(H23*K$19*((U$35+U$37)*U$36)/100) -> 1576.0272 | M23: =H23*M$19*((W$35+W$37)*W$36)/100 -> 2651.121 | N23: =(H23*N$19*((W$35+W$37)*W$36)/100)-(H23*M$19*((W$35+W$37)*W$36)/100) -> 1590.6726 | S23: mar | T23: 91.79 | U23: =(T23+10)*1.25 -> 127.2375 | V23: 63.36 | W23: =(V23+10)*1.25 -> 91.7 | Y23: mar | Z23: 1.6 | AA23: 2.3 | AB23: 2.6 | AC23: 3.8 | AD23: 2 | AE23: 2.7 | AF23: 3.2 | AG23: 4 | AH23: 2.5 | AI23: 3.8 | AJ23: 4.4 | AK23: 6.5
K24: Ökning | L24: =L19/K19-1 -> 0.53333333 | S24: apr | T24: 73.87 | U24: =(T24+10)*1.25 -> 104.8375 | V24: 62.45 | W24: =(V24+10)*1.25 -> 90.5625 | Y24: apr | Z24: 1.5 | AA24: 2 | AB24: 2.4 | AC24: 3.5 | AD24: 1.8 | AE24: 2.2 | AF24: 3 | AG24: 3.5 | AH24: 2 | AI24: 2.8 | AJ24: 3 | AK24: 4
K25: SE 4 Sammanfattning | P25: 2023 | S25: maj | T25: 73.5 | U25: =(T25+10)*1.25 -> 104.375 | V25: 50.58 | W25: =(V25+10)*1.25 -> 75.725 | Y25: maj | Z25: 1 | AA25: 1.5 | AB25: 1.8 | AC25: 2.5 | AD25: 1.2 | AE25: 1.5 | AF25: 2 | AG25: 2.4 | AH25: 0.8 | AI25: 1 | AJ25: 1 | AK25: 1.5
B26: Elbil | C26: SE1-4 | D26: 1500 mil á 2 kr/kWh, 70% hemma | E26: 1500 | F26: 0.7 | G26: 2 | H26: =E26*G26*F26 -> 2100 | L26: BV | M26: hus 1 | N26: nej | P26: =L4+P4 -> 2800.0139 | S26: jun | T26: 103.39 | U26: =(T26+10)*1.25 -> 141.7375 | V26: 62.7 | W26: =(V26+10)*1.25 -> 90.875 | Y26: jun | Z26: 0.8 | AA26: 1.2 | AB26: 1.5 | AC26: 2 | AD26: 0.8 | AE26: 1.2 | AF26: 1.5 | AG26: 1.8 | AH26: 0.6 | AI26: 0.6 | AJ26: 0.6 | AK26: 0.6
N27: sol | P27: =P26+L$20 -> 4770.0479 | S27: jul | T27: 41.76 | U27: =(T27+10)*1.25 -> 64.7 | V27: 43.34 | W27: =(V27+10)*1.25 -> 66.675 | Y27: jul | Z27: 0.8 | AA27: 1.2 | AB27: 1.5 | AC27: 2 | AD27: 0.8 | AE27: 1.2 | AF27: 1.5 | AG27: 1.8 | AH27: 0.6 | AI27: 0.6 | AJ27: 0.6 | AK27: 0.6
N28: elbil | P28: =L4+Q4 -> 3096.0139 | S28: aug | T28: 49.54 | U28: =(T28+10)*1.25 -> 74.425 | V28: 45.93 | W28: =(V28+10)*1.25 -> 69.9125 | Y28: aug | Z28: 0.8 | AA28: 1.2 | AB28: 1.5 | AC28: 2 | AD28: 0.8 | AE28: 1.2 | AF28: 1.5 | AG28: 1.8 | AH28: 0.6 | AI28: 0.6 | AJ28: 0.6 | AK28: 0.6
N29: sol+elbil | P29: =P28+L$20 -> 5066.0479 | S29: sep | T29: 51.33 | U29: =(T29+10)*1.25 -> 76.6625 | V29: 30.67 | W29: =(V29+10)*1.25 -> 50.8375 | Y29: sep | Z29: 0.8 | AA29: 1.2 | AB29: 1.5 | AC29: 2 | AD29: 0.8 | AE29: 1.2 | AF29: 1.5 | AG29: 1.8 | AH29: 0.6 | AI29: 0.6 | AJ29: 0.6 | AK29: 0.6
M30: hus 2 | N30: nej | P30: =L5+P5 -> 3877.7963 | S30: okt | T30: 35.95 | U30: =(T30+10)*1.25 -> 57.4375 | V30: 30.15 | W30: =(V30+10)*1.25 -> 50.1875 | Y30: okt | Z30: 1 | AA30: 2 | AB30: 1.8 | AC30: 3 | AD30: 1 | AE30: 2 | AF30: 2 | AG30: 2.4 | AH30: 1 | AI30: 1.5 | AJ30: 2 | AK30: 3
N31: sol | P31: =P30+L$20 -> 5847.8303 | S31: nov | T31: 84.72 | U31: =(T31+10)*1.25 -> 118.4 | V31: 84.65 | W31: =(V31+10)*1.25 -> 118.3125 | Y31: nov | Z31: 1.5 | AA31: 2.2 | AB31: 2.4 | AC31: 3.5 | AD31: 2 | AE31: 2.5 | AF31: 3 | AG31: 3.5 | AH31: 2 | AI31: 3 | AJ31: 3.8 | AK31: 6
N32: elbil | P32: =L5+Q5 -> 4315.7963 | S32: dec | T32: 81.39 | U32: =(T32+10)*1.25 -> 114.2375 | V32: 70.77 | W32: =(V32+10)*1.25 -> 100.9625 | Y32: dec | Z32: 1.6 | AA32: 2.3 | AB32: 2.6 | AC32: 4 | AD32: 2.2 | AE32: 3 | AF32: 3.6 | AG32: 4.5 | AH32: 3 | AI32: 4 | AJ32: 5.5 | AK32: 7.5
N33: sol+elbil | P33: =P32+L$20 -> 6285.8303 | S33: Medel: | T33: =SUM(T21:T32)/12 -> 74.538333 | U33: =SUM(U21:U32)/12 -> 105.67292 | V33: =SUM(V21:V32)/12 -> 57.003333 | W33: =SUM(W21:W32)/12 -> 83.754167 | Y33: Medel: | Z33: =SUM(Z21:Z32)/12 -> 1.2333333 | AA33: =SUM(AA21:AA32)/12 -> 1.825 | AB33: =SUM(AB21:AB32)/12 -> 2.1333333 | AC33: =SUM(AC21:AC32)/12 -> 3.0583333 | AD33: =SUM(AD21:AD32)/12 -> 1.5166667 | AE33: =SUM(AE21:AE32)/12 -> 2.0583333 | AF33: =SUM(AF21:AF32)/12 -> 2.5166667 | AG33: =SUM(AG21:AG32)/12 -> 3.0916667 | ... AK33: =SUM(AK21:AK32)/12 -> 3.9083333
M34: hus 3 | N34: nej | P34: =L6+P6 -> 5168.5114 | Y34: VP avgiven effekt: | Z34: 6 | AA34: 8 | AB34: 10 | AC34: 14 | AD34: 6 | AE34: 8 | AF34: 10 | AG34: 14 | AH34: 6 | AI34: 8 | AJ34: 10 | AK34: 14
N35: sol | P35: =P34+L$20 -> 7138.5454 | S35: Medel solel: | T35: (juni-sept) | U35: =SUM(U25:U30)/6 -> 86.55625 | W35: =SUM(W25:W30)/6 -> 67.36875 | Y35: Tariffpris: | Z35: 100
N36: elbil | P36: =L6+Q6 -> 5680.5114 | S36: Sol-elpris: | U36: 0.66 | W36: 0.66 | Y36: Reaktionstid, min: | Z36: 20
N37: sol+elbil | P37: =P36+L$20 -> 7650.5454 | S37: Elöverf/skatt: | U37: 100 | W37: 100 | Y37: Reak-tid inkl elbil, min: | Z37: 8
M38: hus 4 | N38: nej | P38: =L7+P7 -> 7254.7844
N39: sol | P39: =P38+L$20 -> 9224.8184 | Y39: jan | Z39: =Z$34/Z21 -> 3.5294118 | AA39: =AA$34/AA21 -> 3.3333333 | AB39: =AB$34/AB21 -> 3.3333333 | AC39: =AC$34/AC21 -> 3.3333333 | AD39: =AD$34/AD21 -> 2.6086957 | AE39: =AE$34/AE21 -> 2.6666667 | AF39: =AF$34/AF21 -> 2.7027027 | AG39: =AG$34/AG21 -> 2.9166667 | ... AK39: =AK$34/AK21 -> 1.75
N40: elbil | P40: =L7+Q7 -> 7988.7844
N41: sol+elbil | P41: =P40+L$20 -> 9958.8184
L42: LV | M42: hus 1 | N42: nej | P42: =L8+P8 -> 3686.0796
...

Sheet SE3
B1: VP-typ | C1: Hustyp | D1: Förklaring | E1: Antal kvm | F1: ålder | G1: Kwh/kvm/år | H1: Förbrukning värme+vv | J1: SPO 2023 energikostnad, besparing | L1: SPO 2024 energikostnad, besparing | O1: Effekttariffer besparing per år
J2: Besparing %: | K2: 0.26 | L2: Besparing %: | M2: 0.25 | O2: utan elbil | P2: inkl elbil
J3: utan styrning | K3: besparing styrning | L3: utan styrning | M3: besparing styrning | R3: Teckenförklaring
B4: MV | C4: Hus 1 | D4: 1 plans 100 kvm, 6 kW avgiven effekt | E4: 120 | F4: 1990 | G4: 55 | H4: =E4*G4 -> 6600 | J4: =H4/100*T$33 -> 5712.6438 | K4: =H4/100*T$33*K$2 -> 1485.2874 | L4: =H4/100*V$33 -> 4211.5562 | M4: =H4/100*V$33*M$2 -> 1052.8891 | O4: =$Y33*$Y$35*12*((60-$Y$36)/60) -> 690.66667 | P4: =$Y33*$Y$35*12*((60-$Y$37)/60) -> 897.86667 | R4: ok att ändra, testa
C5: Hus 2 | D5: 1-plan villa 150 kvm, 8 kW avgiven effekt | E5: 160 | F5: 2010 | G5: 55 | H5: =E5*G5 -> 8800 | J5: =H5/100*T$33 -> 7616.8583 | K5: =H5/100*T$33*K$2 -> 1980.3832 | L5: =H5/100*V$33 -> 5615.4083 | M5: =H5/100*V$33*M$2 -> 1403.8521 | O5: =Z33*Y$35*12*((60-Y$36)/60) -> 1022 | P5: =$Z33*$Y$35*12*((60-$Y$37)/60) -> 1328.6
C6: Hus 3 | D6: 1,5 plan villa 200 kvm, 10 kW avgiven effekt | E6: 210 | F6: 1960 | G6: 60 | H6: =E6*G6 -> 12600 | J6: =H6/100*T$33 -> 10905.956 | K6: =H6/100*T$33*K$2 -> 2835.5486 | L6: =H6/100*V$33 -> 8040.2437 | M6: =H6/100*V$33*M$2 -> 2010.0609 | O6: =AA33*Y$35*12*((60-Y$36)/60) -> 1194.6667 | P6: =$AA33*$Y$35*12*((60-$Y$37)/60) -> 1553.0667
C7: Hus 4 | D7: 2-plan villa 250 kvm+, 14 kW avgiven effekt | E7: 250 | F7: 1970 | G7: 70 | H7: =E7*G7 -> 17500 | J7: =H7/100*T$33 -> 15147.161 | K7: =H7/100*T$33*K$2 -> 3938.262 | L7: =H7/100*V$33 -> 11167.005 | M7: =H7/100*V$33*M$2 -> 2791.7513 | O7: =AB33*Y$35*12*((60-Y$36)/60) -> 1712.6667 | P7: =$AB33*$Y$35*12*((60-$Y$37)/60) -> 2226.4667
B8: LV | C8: Hus 1 | E8: 120 | G8: 75 | H8: =E8*G8 -> 9000 | J8: =H8/100*T$33 -> 7789.9688 | K8: =H8/100*T$33*K$2 -> 2025.3919 | L8: =H8/100*V$33 -> 5743.0312 | M8: =H8/100*V$33*M$2 -> 1435.7578 | O8: =$AC33*$Y$35*12*((60-$Y$36)/60) -> 849.33333 | P8: =$AC33*$Y$35*12*((60-$Y$37)/60) -> 1104.1333
C9: Hus 2 | E9: 160 | G9: 70 | H9: =E9*G9 -> 11200 | J9: =H9/100*T$33 -> 9694.1833 | K9: =H9/100*T$33*K$2 -> 2520.4877 | L9: =H9/100*V$33 -> 7146.8833 | M9: =H9/100*V$33*M$2 -> 1786.7208 | O9: =$AD33*$Y$35*12*((60-$Y$36)/60) -> 1152.6667 | P9: =$AD33*$Y$35*12*((60-$Y$37)/60) -> 1498.4667
C10: Hus 3 | E10: 210 | G10: 85 | H10: =E10*G10 -> 17850 | J10: =H10/100*T$33 -> 15450.105 | K10: =H10/100*T$33*K$2 -> 4017.0272 | L10: =H10/100*V$33 -> 11390.345 | M10: =H10/100*V$33*M$2 -> 2847.5863 | O10: =$AE33*$Y$35*12*((60-$Y$36)/60) -> 1409.3333 | P10: =$AE33*$Y$35*12*((60-$Y$37)/60) -> 1832.1333
C11: Hus 4 | E11: 250 | G11: 90 | H11: =E11*G11 -> 22500 | J11: =H11/100*T$33 -> 19474.922 | K11: =H11/100*T$33*K$2 -> 5063.4797 | L11: =H11/100*V$33 -> 14357.578 | M11: =H11/100*V$33*M$2 -> 3589.3945 | O11: =$AF33*$Y$35*12*((60-$Y$36)/60) -> 1731.3333 | P11: =$AF33*$Y$35*12*((60-$Y$37)/60) -> 2250.7333
B12: FL | C12: Hus 1 | E12: 120 | G12: 100 | H12: =E12*G12 -> 12000 | J12: =H12/100*T$33 -> 10386.625 | K12: =H12/100*T$33*K$2 -> 2700.5225 | L12: =H12/100*V$33 -> 7657.375 | M12: =H12/100*V$33*M$2 -> 1914.3437 | O12: =$AG33*$Y$35*12*((60-$Y$36)/60) -> 919.33333 | P12: =$AG33*$Y$35*12*((60-$Y$37)/60) -> 1195.1333
C13: Hus 2 | E13: 160 | G13: 110 | H13: =E13*G13 -> 17600 | J13: =H13/100*T$33 -> 15233.717 | K13: =H13/100*T$33*K$2 -> 3960.7663 | L13: =H13/100*V$33 -> 11230.817 | M13: =H13/100*V$33*M$2 -> 2807.7042 | O13: =$AH33*$Y$35*12*((60-$Y$36)/60) -> 1236.6667 | P13: =$AH33*$Y$35*12*((60-$Y$37)/60) -> 1607.6667
C14: Hus 3 | E14: 210 | G14: 120 | H14: =E14*G14 -> 25200 | J14: =H14/100*T$33 -> 21811.913 | K14: =H14/100*T$33*K$2 -> 5671.0973 | L14: =H14/100*V$33 -> 16080.487 | M14: =H14/100*V$33*M$2 -> 4020.1219 | O14: =$AI33*$Y$35*12*((60-$Y$36)/60) -> 1544.6667 | P14: =$AI33*$Y$35*12*((60-$Y$37)/60) -> 2008.0667
C15: Hus 4 | E15: 250 | G15: 130 | H15: =E15*G15 -> 32500 | J15: =H15/100*T$33 -> 28130.443 | K15: =H15/100*T$33*K$2 -> 7313.9151 | L15: =H15/100*V$33 -> 20738.724 | M15: =H15/100*V$33*M$2 -> 5184.681 | O15: =$AG33*$Y$35*12*((60-$Y$36)/60) -> 919.33333 | P15: =$AJ33*$Y$35*12*((60-$Y$37)/60) -> 2845.2667
J17: Sol 2023 egenanvändning före/efter | L17: Sol 2024 energikostnad, besparing
J19: 0.3 | K19: 0.46 | L19: 0.3 | M19: 0.48 | R19: Elpriser tabell | S19: 2023 | U19: 2024 | X19: Effekttabell tariffer | Y19: MV tillgänglig effekt | AC19: LV tillgänglig effekt | AG19: FL tillgänglig effekt
B20: Sol | C20: SE3 | D20: 25 paneler med 400 Wp | E20: 25 | G20: 380 | H20: =E20*G20 -> 9500 | J20: =H20*J$19*((T$35+T$37)*T$36)/100 -> 2994.1993 | K20: =(H20*K$19*((T$35+T$37)*T$36)/100)-(H20*J$19*((T$35+T$37)*T$36)/100) -> 1596.9063 | L20: =H20*L$19*((V$35+V$37)*V$36)/100 -> 2321.6634 | M20: =(H20*M$19*((V$35+V$37)*V$36)/100)-(H20*L$19*((V$35+V$37)*V$36)/100) -> 1392.9981 | S20: el, exkl moms | T20: el, inkl moms+påslag | U20: exkl moms | V20: inkl moms+påslag | Y20: Hus 1 | Z20: Hus 2 | AA20: Hus 3 | AB20: Hus 4 | AC20: Hus 1 | AD20: Hus 2 | AE20: Hus 3 | AF20: Hus 4 | AG20: Hus 1 | AH20: Hus 2 | AI20: Hus 3 | AJ20: Hus 4
J21: =H21*J$19*((T$35+T$37)*T$36)/100 -> 0 | K21: =(H21*K$19*((T$35+T$37)*T$36)/100)-(H21*J$19*((T$35+T$37)*T$36)/100) -> 0 | L21: =H21*L$19*((V$35+V$37)*V$36)/100 -> 0 | M21: =(H21*M$19*((V$35+V$37)*V$36)/100)-(H21*L$19*((V$35+V$37)*V$36)/100) -> 0 | R21: jan | S21: 92.58 | T21: =(S21+10)*1.25 -> 128.225 | U21: 80.3 | V21: =(U21+10)*1.25 -> 112.875 | X21: jan | Y21: 1.7 | Z21: 2.4 | AA21: 3 | AB21: 4.2 | AC21: 2.3 | AD21: 3 | AE21: 3.7 | AF21: 4.8 | AG21: 3 | AH21: 4 | AI21: 5.5 | AJ21: 8
J22: =H22*J$19*((T$35+T$37)*T$36)/100 -> 0 | K22: =(H22*K$19*((T$35+T$37)*T$36)/100)-(H22*J$19*((T$35+T$37)*T$36)/100) -> 0 | L22: =H22*L$19*((V$35+V$37)*V$36)/100 -> 0 | M22: =(H22*M$19*((V$35+V$37)*V$36)/100)-(H22*L$19*((V$35+V$37)*V$36)/100) -> 0 | R22: feb | S22: 82.54 | T22: =(S22+10)*1.25 -> 115.675 | U22: 50.34 | V22: =(U22+10)*1.25 -> 75.425 | X22: feb | Y22: 1.7 | Z22: 2.4 | AA22: 3 | AB22: 4.2 | AC22: 2.5 | AD22: 3 | AE22: 3.7 | AF22: 4.8 | AG22: 3 | AH22: 4 | AI22: 5.5 | AJ22: 8
J23: =H23*J$19*((T$35+T$37)*T$36)/100 -> 0 | K23: =(H23*K$19*((T$35+T$37)*T$36)/100)-(H23*J$19*((T$35+T$37)*T$36)/100) -> 0 | L23: =H23*L$19*((V$35+V$37)*V$36)/100 -> 0 | M23: =(H23*M$19*((V$35+V$37)*V$36)/100)-(H23*L$19*((V$35+V$37)*V$36)/100) -> 0 | R23: mar | S23: 80.62 | T23: =(S23+10)*1.25 -> 113.275 | U23: 59.47 | V23: =(U23+10)*1.25 -> 86.8375 | X23: mar | Y23: 1.6 | Z23: 2.3 | AA23: 2.6 | AB23: 3.8 | AC23: 2 | AD23: 2.7 | AE23: 3.2 | AF23: 4 | AG23: 2.5 | AH23: 3.8 | AI23: 4.4 | AJ23: 6.5
R24: apr | S24: 68.7 | T24: =(S24+10)*1.25 -> 98.375 | U24: 56.31 | V24: =(U24+10)*1.25 -> 82.8875 | X24: apr | Y24: 1.5 | Z24: 2 | AA24: 2.4 | AB24: 3.5 | AC24: 1.8 | AD24: 2.2 | AE24: 3 | AF24: 3.5 | AG24: 2 | AH24: 2.8 | AI24: 3 | AJ24: 4
J25: SE 3 Sammanfattning | O25: 2023 | R25: maj | S25: 39.02 | T25: =(S25+10)*1.25 -> 61.275 | U25: 23.71 | V25: =(U25+10)*1.25 -> 42.1375 | X25: maj | Y25: 1 | Z25: 1.5 | AA25: 1.8 | AB25: 2.5 | AC25: 1.2 | AD25: 1.5 | AE25: 2 | AF25: 2.4 | AG25: 0.8 | AH25: 1 | AI25: 1 | AJ25: 1.5
B26: Elbil | C26: SE1-4 | D26: 1500 mil á 2 kr/kWh, 70% hemma | E26: 1500 | F26: 0.7 | G26: 2 | H26: =E26*G26*F26 -> 2100 | K26: BV | L26: hus 1 | M26: nej | O26: =K4+O4 -> 2175.954 | R26: jun | S26: 53.06 | T26: =(S26+10)*1.25 -> 78.825 | U26: 27.27 | V26: =(U26+10)*1.25 -> 46.5875 | X26: jun | Y26: 0.8 | Z26: 1.2 | AA26: 1.5 | AB26: 2 | AC26: 0.8 | AD26: 1.2 | AE26: 1.5 | AF26: 1.8 | AG26: 0.6 | AH26: 0.6 | AI26: 0.6 | AJ26: 0.6
M27: sol | O27: =O26+K$20 -> 3772.8603 | R27: jul | S27: 37.65 | T27: =(S27+10)*1.25 -> 59.5625 | U27: 20.72 | V27: =(U27+10)*1.25 -> 38.4 | X27: jul | Y27: 0.8 | Z27: 1.2 | AA27: 1.5 | AB27: 2 | AC27: 0.8 | AD27: 1.2 | AE27: 1.5 | AF27: 1.8 | AG27: 0.6 | AH27: 0.6 | AI27: 0.6 | AJ27: 0.6
M28: elbil | O28: =K4+P4 -> 2383.154 | R28: aug | S28: 36.96 | T28: =(S28+10)*1.25 -> 58.7 | U28: 8.54 | V28: =(U28+10)*1.25 -> 23.175 | X28: aug | Y28: 0.8 | Z28: 1.2 | AA28: 1.5 | AB28: 2 | AC28: 0.8 | AD28: 1.2 | AE28: 1.5 | AF28: 1.8 | AG28: 0.6 | AH28: 0.6 | AI28: 0.6 | AJ28: 0.6
M29: sol+elbil | O29: =O28+K$20 -> 3980.0603 | R29: sep | S29: 24.32 | T29: =(S29+10)*1.25 -> 42.9 | U29: 16.44 | V29: =(U29+10)*1.25 -> 33.05 | X29: sep | Y29: 0.8 | Z29: 1.2 | AA29: 1.5 | AB29: 2 | AC29: 0.8 | AD29: 1.2 | AE29: 1.5 | AF29: 1.8 | AG29: 0.6 | AH29: 0.6 | AI29: 0.6 | AJ29: 0.6
L30: hus 2 | M30: nej | O30: =K5+O5 -> 3002.3832 | R30: okt | S30: 33.06 | T30: =(S30+10)*1.25 -> 53.825 | U30: 22.97 | V30: =(U30+10)*1.25 -> 41.2125 | X30: okt | Y30: 1 | Z30: 2 | AA30: 1.8 | AB30: 3 | AC30: 1 | AD30: 2 | AE30: 2 | AF30: 2.4 | AG30: 1 | AH30: 1.5 | AI30: 2 | AJ30: 3
M31: sol | O31: =O30+K$20 -> 4599.2895 | R31: nov | S31: 82.13 | T31: =(S31+10)*1.25 -> 115.1625 | U31: 66.95 | V31: =(U31+10)*1.25 -> 96.1875 | X31: nov | Y31: 1.5 | Z31: 2.2 | AA31: 2.4 | AB31: 3.5 | AC31: 2 | AD31: 2.5 | AE31: 3 | AF31: 3.5 | AG31: 2 | AH31: 3 | AI31: 3.8 | AJ31: 6
M32: elbil | O32: =K5+P5 -> 3308.9832 | R32: dec | S32: 80.29 | T32: =(S32+10)*1.25 -> 112.8625 | U32: 59.57 | V32: =(U32+10)*1.25 -> 86.9625 | X32: dec | Y32: 1.6 | Z32: 2.3 | AA32: 2.6 | AB32: 4 | AC32: 2.2 | AD32: 3 | AE32: 3.6 | AF32: 4.5 | AG32: 3 | AH32: 4 | AI32: 5.5 | AJ32: 7.5
M33: sol+elbil | O33: =O32+K$20 -> 4905.8895 | R33: Medel: | S33: =SUM(S21:S32)/12 -> 59.244167 | T33: =SUM(T21:T32)/12 -> 86.555208 | U33: =SUM(U21:U32)/12 -> 41.049167 | V33: =SUM(V21:V32)/12 -> 63.811458 | X33: Medel: | Y33: 1.2333333 | Z33: 1.825 | AA33: 2.1333333 | AB33: 3.0583333 | AC33: 1.5166667 | AD33: 2.0583333 | AE33: 2.5166667 | AF33: 3.0916667 | AG33: 1.6416667 | AH33: 2.2083333 | AI33: 2.7583333 | AJ33: 3.9083333
L34: hus 3 | M34: nej | O34: =K6+O6 -> 4030.2153 | X34: VP avgiven effekt: | Y34: 6 | Z34: 8 | AA34: 10 | AB34: 14 | AC34: 6 | AD34: 8 | AE34: 10 | AF34: 14 | AG34: 6 | AH34: 8 | AI34: 10 | AJ34: 14
M35: sol | O35: =O34+K$20 -> 5627.1216 | R35: Medel solel: | S35: (juni-sept) | T35: =SUM(T25:T30)/6 -> 59.18125 | V35: =SUM(V25:V30)/6 -> 37.427083 | X35: Tariffpris: | Y35: 70
M36: elbil | O36: =K6+P6 -> 4388.6153 | R36: Sol-elpris: | T36: 0.66 | V36: 0.66 | X36: Reaktionstid, min: | Y36: 20
M37: sol+elbil | O37: =O36+K$20 -> 5985.5216 | R37: Elöverf/skatt: | T37: 100 | V37: 86 | X37: Reak-tid inkl elbil, min: | Y37: 8
L38: hus 4 | M38: nej | O38: =K7+O7 -> 5650.9286
M39: sol | O39: =O38+K$20 -> 7247.8349
M40: elbil | O40: =K7+P7 -> 6164.7286
M41: sol+elbil | O41: =O40+K$20 -> 7761.6349
K42: LV | L42: hus 1 | M42: nej | O42: =K8+O8 -> 2874.7252
...

Sheet SE2
B1: VP-typ | C1: Hustyp | D1: Förklaring | E1: Antal kvm | F1: ålder | G1: Kwh/kvm/år | H1: Förbrukning värme+vv | J1: SPO 2023 energikostnad, besparing | L1: SPO 2024 energikostnad, besparing | O1: Effekttariffer besparing per år
J2: Besparing %: | K2: 0.26 | L2: Besparing %: | M2: 0.25 | O2: utan elbil | P2: inkl elbil
J3: utan styrning | K3: besparing styrning | L3: utan styrning | M3: besparing styrning | R3: Teckenförklaring
B4: MV | C4: Hus 1 | D4: 1 plans 100 kvm, 6 kW avgiven effekt | E4: 120 | F4: 1990 | G4: 55 | H4: =E4*G4 -> 6600 | J4: =H4/100*T$33 -> 4598.3438 | K4: =H4/100*T$33*K$2 -> 1195.5694 | L4: =H4/100*V$33 -> 3149.2312 | M4: =H4/100*V$33*M$2 -> 787.30781 | O4: =$Y33*$Y$35*12*((60-$Y$36)/60) -> 690.66667 | P4: =$Y33*$Y$35*12*((60-$Y$37)/60) -> 897.86667 | R4: ok att ändra, testa
C5: Hus 2 | D5: 1-plan villa 150 kvm, 8 kW avgiven effekt | E5: 160 | F5: 2010 | G5: 55 | H5: =E5*G5 -> 8800 | J5: =H5/100*T$33 -> 6131.125 | K5: =H5/100*T$33*K$2 -> 1594.0925 | L5: =H5/100*V$33 -> 4198.975 | M5: =H5/100*V$33*M$2 -> 1049.7437 | O5: =Z33*Y$35*12*((60-Y$36)/60) -> 1022 | P5: =$Z33*$Y$35*12*((60-$Y$37)/60) -> 1328.6
C6: Hus 3 | D6: 1,5 plan villa 200 kvm, 10 kW avgiven effekt | E6: 210 | F6: 1960 | G6: 60 | H6: =E6*G6 -> 12600 | J6: =H6/100*T$33 -> 8778.6562 | K6: =H6/100*T$33*K$2 -> 2282.4506 | L6: =H6/100*V$33 -> 6012.1687 | M6: =H6/100*V$33*M$2 -> 1503.0422 | O6: =AA33*Y$35*12*((60-Y$36)/60) -> 1194.6667 | P6: =$AA33*$Y$35*12*((60-$Y$37)/60) -> 1553.0667
C7: Hus 4 | D7: 2-plan villa 250 kvm+, 14 kW avgiven effekt | E7: 250 | F7: 1970 | G7: 70 | H7: =E7*G7 -> 17500 | J7: =H7/100*T$33 -> 12192.578 | K7: =H7/100*T$33*K$2 -> 3170.0703 | L7: =H7/100*V$33 -> 8350.2344 | M7: =H7/100*V$33*M$2 -> 2087.5586 | O7: =AB33*Y$35*12*((60-Y$36)/60) -> 1712.6667 | P7: =$AB33*$Y$35*12*((60-$Y$37)/60) -> 2226.4667
B8: LV | C8: Hus 1 | E8: 120 | G8: 75 | H8: =E8*G8 -> 9000 | J8: =H8/100*T$33 -> 6270.4688 | K8: =H8/100*T$33*K$2 -> 1630.3219 | L8: =H8/100*V$33 -> 4294.4062 | M8: =H8/100*V$33*M$2 -> 1073.6016 | O8: =$AC33*$Y$35*12*((60-$Y$36)/60) -> 849.33333 | P8: =$AC33*$Y$35*12*((60-$Y$37)/60) -> 1104.1333
C9: Hus 2 | E9: 160 | G9: 70 | H9: =E9*G9 -> 11200 | J9: =H9/100*T$33 -> 7803.25 | K9: =H9/100*T$33*K$2 -> 2028.845 | L9: =H9/100*V$33 -> 5344.15 | M9: =H9/100*V$33*M$2 -> 1336.0375 | O9: =$AD33*$Y$35*12*((60-$Y$36)/60) -> 1152.6667 | P9: =$AD33*$Y$35*12*((60-$Y$37)/60) -> 1498.4667
C10: Hus 3 | E10: 210 | G10: 85 | H10: =E10*G10 -> 17850 | J10: =H10/100*T$33 -> 12436.43 | K10: =H10/100*T$33*K$2 -> 3233.4717 | L10: =H10/100*V$33 -> 8517.2391 | M10: =H10/100*V$33*M$2 -> 2129.3098 | O10: =$AE33*$Y$35*12*((60-$Y$36)/60) -> 1409.3333 | P10: =$AE33*$Y$35*12*((60-$Y$37)/60) -> 1832.1333
C11: Hus 4 | E11: 250 | G11: 90 | H11: =E11*G11 -> 22500 | J11: =H11/100*T$33 -> 15676.172 | K11: =H11/100*T$33*K$2 -> 4075.8047 | L11: =H11/100*V$33 -> 10736.016 | M11: =H11/100*V$33*M$2 -> 2684.0039 | O11: =$AF33*$Y$35*12*((60-$Y$36)/60) -> 1731.3333 | P11: =$AF33*$Y$35*12*((60-$Y$37)/60) -> 2250.7333
B12: FL | C12: Hus 1 | E12: 120 | G12: 100 | H12: =E12*G12 -> 12000 | J12: =H12/100*T$33 -> 8360.625 | K12: =H12/100*T$33*K$2 -> 2173.7625 | L12: =H12/100*V$33 -> 5725.875 | M12: =H12/100*V$33*M$2 -> 1431.4687 | O12: =$AG33*$Y$35*12*((60-$Y$36)/60) -> 919.33333 | P12: =$AG33*$Y$35*12*((60-$Y$37)/60) -> 1195.1333
C13: Hus 2 | E13: 160 | G13: 110 | H13: =E13*G13 -> 17600 | J13: =H13/100*T$33 -> 12262.25 | K13: =H13/100*T$33*K$2 -> 3188.185 | L13: =H13/100*V$33 -> 8397.95 | M13: =H13/100*V$33*M$2 -> 2099.4875 | O13: =$AH33*$Y$35*12*((60-$Y$36)/60) -> 1236.6667 | P13: =$AH33*$Y$35*12*((60-$Y$37)/60) -> 1607.6667
C14: Hus 3 | E14: 210 | G14: 120 | H14: =E14*G14 -> 25200 | J14: =H14/100*T$33 -> 17557.312 | K14: =H14/100*T$33*K$2 -> 4564.9012 | L14: =H14/100*V$33 -> 12024.337 | M14: =H14/100*V$33*M$2 -> 3006.0844 | O14: =$AI33*$Y$35*12*((60-$Y$36)/60) -> 1544.6667 | P14: =$AI33*$Y$35*12*((60-$Y$37)/60) -> 2008.0667
C15: Hus 4 | E15: 250 | G15: 130 | H15: =E15*G15 -> 32500 | J15: =H15/100*T$33 -> 22643.359 | K15: =H15/100*T$33*K$2 -> 5887.2734 | L15: =H15/100*V$33 -> 15507.578 | M15: =H15/100*V$33*M$2 -> 3876.8945 | O15: =$AG33*$Y$35*12*((60-$Y$36)/60) -> 919.33333 | P15: =$AJ33*$Y$35*12*((60-$Y$37)/60) -> 2845.2667
J17: Sol 2023 egenanvändning före/efter | L17: Sol 2024 energikostnad, besparing
J19: 0.3 | K19: 0.46 | L19: 0.3 | M19: 0.45 | R19: Elpriser tabell | S19: 2023 | U19: 2024 | X19: Effekttabell tariffer | Y19: MV tillgänglig effekt | AC19: LV tillgänglig effekt | AG19: FL tillgänglig effekt
B20: Sol | C20: SE2 | D20: 25 paneler med 400 Wp | E20: 25 | G20: 340 | H20: 8500 | J20: =H20*J$19*((T$35+T$37)*T$36)/100 -> 2486.2118 | K20: =(H20*K$19*((T$35+T$37)*T$36)/100)-(H20*J$19*((T$35+T$37)*T$36)/100) -> 1325.9796 | L20: =H20*L$19*((V$35+V$37)*V$36)/100 -> 1991.1643 | M20: =(H20*M$19*((V$35+V$37)*V$36)/100)-(H20*L$19*((V$35+V$37)*V$36)/100) -> 995.58216 | S20: el, exkl moms | T20: el, inkl moms+påslag | U20: exkl moms | V20: inkl moms+påslag | Y20: Hus 1 | Z20: Hus 2 | AA20: Hus 3 | AB20: Hus 4 | AC20: Hus 1 | AD20: Hus 2 | AE20: Hus 3 | AF20: Hus 4 | AG20: Hus 1 | AH20: Hus 2 | AI20: Hus 3 | AJ20: Hus 4
J21: =H21*J$19*((T$35+T$37)*T$36)/100 -> 0 | K21: =(H21*K$19*((T$35+T$37)*T$36)/100)-(H21*J$19*((T$35+T$37)*T$36)/100) -> 0 | L21: =H21*L$19*((V$35+V$37)*V$36)/100 -> 0 | M21: =(H21*M$19*((V$35+V$37)*V$36)/100)-(H21*L$19*((V$35+V$37)*V$36)/100) -> 0 | R21: jan | S21: 70.38 | T21: =(S21+10)*1.25 -> 100.475 | U21: 61.2 | V21: =(U21+10)*1.25 -> 89 | X21: jan | Y21: 1.7 | Z21: 2.4 | AA21: 3 | AB21: 4.2 | AC21: 2.3 | AD21: 3 | AE21: 3.7 | AF21: 4.8 | AG21: 3 | AH21: 4 | AI21: 5.5 | AJ21: 8
J22: =H22*J$19*((T$35+T$37)*T$36)/100 -> 0 | K22: =(H22*K$19*((T$35+T$37)*T$36)/100)-(H22*J$19*((T$35+T$37)*T$36)/100) -> 0 | L22: =H22*L$19*((V$35+V$37)*V$36)/100 -> 0 | M22: =(H22*M$19*((V$35+V$37)*V$36)/100)-(H22*L$19*((V$35+V$37)*V$36)/100) -> 0 | R22: feb | S22: 52.03 | T22: =(S22+10)*1.25 -> 77.5375 | U22: 44.94 | V22: =(U22+10)*1.25 -> 68.675 | X22: feb | Y22: 1.7 | Z22: 2.4 | AA22: 3 | AB22: 4.2 | AC22: 2.5 | AD22: 3 | AE22: 3.7 | AF22: 4.8 | AG22: 3 | AH22: 4 | AI22: 5.5 | AJ22: 8
J23: =H23*J$19*((T$35+T$37)*T$36)/100 -> 0 | K23: =(H23*K$19*((T$35+T$37)*T$36)/100)-(H23*J$19*((T$35+T$37)*T$36)/100) -> 0 | L23: =H23*L$19*((V$35+V$37)*V$36)/100 -> 0 | M23: =(H23*M$19*((V$35+V$37)*V$36)/100)-(H23*L$19*((V$35+V$37)*V$36)/100) -> 0 | R23: mar | S23: 56.49 | T23: =(S23+10)*1.25 -> 83.1125 | U23: 56.61 | V23: =(U23+10)*1.25 -> 83.2625 | X23: mar | Y23: 1.6 | Z23: 2.3 | AA23: 2.6 | AB23: 3.8 | AC23: 2 | AD23: 2.7 | AE23: 3.2 | AF23: 4 | AG23: 2.5 | AH23: 3.8 | AI23: 4.4 | AJ23: 6.5
R24: apr | S24: 66.47 | T24: =(S24+10)*1.25 -> 95.5875 | U24: 50.79 | V24: =(U24+10)*1.25 -> 75.9875 | X24: apr | Y24: 1.5 | Z24: 2 | AA24: 2.4 | AB24: 3.5 | AC24: 1.8 | AD24: 2.2 | AE24: 3 | AF24: 3.5 | AG24: 2 | AH24: 2.8 | AI24: 3 | AJ24: 4
J25: SE 2 Sammanfattning | O25: 2023 | R25: maj | S25: 27.84 | T25: =(S25+10)*1.25 -> 47.3 | U25: 17.64 | V25: =(U25+10)*1.25 -> 34.55 | X25: maj | Y25: 1 | Z25: 1.5 | AA25: 1.8 | AB25: 2.5 | AC25: 1.2 | AD25: 1.5 | AE25: 2 | AF25: 2.4 | AG25: 0.8 | AH25: 1 | AI25: 1 | AJ25: 1.5
B26: Elbil | C26: SE1-4 | D26: 1500 mil á 2 kr/kWh, 70% hemma | E26: 1500 | F26: 0.7 | G26: 2 | H26: =E26*G26*F26 -> 2100 | K26: BV | L26: hus 1 | M26: nej | O26: =K4+O4 -> 1886.236 | R26: jun | S26: 51.61 | T26: =(S26+10)*1.25 -> 77.0125 | U26: 24.04 | V26: =(U26+10)*1.25 -> 42.55 | X26: jun | Y26: 0.8 | Z26: 1.2 | AA26: 1.5 | AB26: 2 | AC26: 0.8 | AD26: 1.2 | AE26: 1.5 | AF26: 1.8 | AG26: 0.6 | AH26: 0.6 | AI26: 0.6 | AJ26: 0.6
M27: sol | O27: =O26+K$20 -> 3212.2156 | R27: jul | S27: 37.4 | T27: =(S27+10)*1.25 -> 59.25 | U27: 20.49 | V27: =(U27+10)*1.25 -> 38.1125 | X27: jul | Y27: 0.8 | Z27: 1.2 | AA27: 1.5 | AB27: 2 | AC27: 0.8 | AD27: 1.2 | AE27: 1.5 | AF27: 1.8 | AG27: 0.6 | AH27: 0.6 | AI27: 0.6 | AJ27: 0.6
M28: elbil | O28: =K4+P4 -> 2093.436 | R28: aug | S28: 23.76 | T28: =(S28+10)*1.25 -> 42.2 | U28: 8.51 | V28: =(U28+10)*1.25 -> 23.1375 | X28: aug | Y28: 0.8 | Z28: 1.2 | AA28: 1.5 | AB28: 2 | AC28: 0.8 | AD28: 1.2 | AE28: 1.5 | AF28: 1.8 | AG28: 0.6 | AH28: 0.6 | AI28: 0.6 | AJ28: 0.6
M29: sol+elbil | O29: =O28+K$20 -> 3419.4156 | R29: sep | S29: 10.89 | T29: =(S29+10)*1.25 -> 26.1125 | U29: 10.89 | V29: =(U29+10)*1.25 -> 26.1125 | X29: sep | Y29: 0.8 | Z29: 1.2 | AA29: 1.5 | AB29: 2 | AC29: 0.8 | AD29: 1.2 | AE29: 1.5 | AF29: 1.8 | AG29: 0.6 | AH29: 0.6 | AI29: 0.6 | AJ29: 0.6
L30: hus 2 | M30: nej | O30: =K5+O5 -> 2616.0925 | R30: okt | S30: 17.58 | T30: =(S30+10)*1.25 -> 34.475 | U30: 13.52 | V30: =(U30+10)*1.25 -> 29.4 | X30: okt | Y30: 1 | Z30: 2 | AA30: 1.8 | AB30: 3 | AC30: 1 | AD30: 2 | AE30: 2 | AF30: 2.4 | AG30: 1 | AH30: 1.5 | AI30: 2 | AJ30: 3
M31: sol | O31: =O30+K$20 -> 3942.0721 | R31: nov | S31: 60.9 | T31: =(S31+10)*1.25 -> 88.625 | U31: 18.09 | V31: =(U31+10)*1.25 -> 35.1125 | X31: nov | Y31: 1.5 | Z31: 2.2 | AA31: 2.4 | AB31: 3.5 | AC31: 2 | AD31: 2.5 | AE31: 3 | AF31: 3.5 | AG31: 2 | AH31: 3 | AI31: 3.8 | AJ31: 6
M32: elbil | O32: =K5+P5 -> 2922.6925 | R32: dec | S32: 73.5 | T32: =(S32+10)*1.25 -> 104.375 | U32: 11.35 | V32: =(U32+10)*1.25 -> 26.6875 | X32: dec | Y32: 1.6 | Z32: 2.3 | AA32: 2.6 | AB32: 4 | AC32: 2.2 | AD32: 3 | AE32: 3.6 | AF32: 4.5 | AG32: 3 | AH32: 4 | AI32: 5.5 | AJ32: 7.5
M33: sol+elbil | O33: =O32+K$20 -> 4248.6721 | R33: Medel: | S33: =SUM(S21:S32)/12 -> 45.7375 | T33: =SUM(T21:T32)/12 -> 69.671875 | U33: =SUM(U21:U32)/12 -> 28.1725 | V33: =SUM(V21:V32)/12 -> 47.715625 | X33: Medel: | Y33: 1.2333333 | Z33: 1.825 | AA33: 2.1333333 | AB33: 3.0583333 | AC33: 1.5166667 | AD33: 2.0583333 | AE33: 2.5166667 | AF33: 3.0916667 | AG33: 1.6416667 | AH33: 2.2083333 | AI33: 2.7583333 | AJ33: 3.9083333
L34: hus 3 | M34: nej | O34: =K6+O6 -> 3477.1173 | X34: VP avgiven effekt: | Y34: 6 | Z34: 8 | AA34: 10 | AB34: 14 | AC34: 6 | AD34: 8 | AE34: 10 | AF34: 14 | AG34: 6 | AH34: 8 | AI34: 10 | AJ34: 14
M35: sol | O35: =O34+K$20 -> 4803.0969 | R35: Medel solel: | S35: (juni-sept) | T35: =SUM(T25:T30)/6 -> 47.725 | V35: =SUM(V25:V30)/6 -> 32.310417 | X35: Tariffpris: | Y35: 70
M36: elbil | O36: =K6+P6 -> 3835.5173 | R36: Sol-elpris: | T36: 0.66 | V36: 0.66 | X36: Reaktionstid, min: | Y36: 20
M37: sol+elbil | O37: =O36+K$20 -> 5161.4969 | R37: Elöverf/skatt: | T37: 100 | V37: 86 | X37: Reak-tid inkl elbil, min: | Y37: 8
L38: hus 4 | M38: nej | O38: =K7+O7 -> 4882.737
M39: sol | O39: =O38+K$20 -> 6208.7166
M40: elbil | O40: =K7+P7 -> 5396.537
M41: sol+elbil | O41: =O40+K$20 -> 6722.5166
K42: LV | L42: hus 1 | M42: nej | O42: =K8+O8 -> 2479.6552
...

Sheet SE1
B1: VP-typ | C1: Hustyp | D1: Förklaring | E1: Antal kvm | F1: ålder | G1: Kwh/kvm/år | H1: Förbrukning värme+vv | J1: SPO 2023 energikostnad, besparing | L1: SPO 2024 energikostnad, besparing | O1: Effekttariffer besparing per år
J2: Besparing %: | K2: 0.26 | L2: Besparing %: | M2: 0.25 | O2: utan elbil | P2: inkl elbil
J3: utan styrning | K3: besparing styrning | L3: utan styrning | M3: besparing styrning | R3: Teckenförklaring
B4: MV | C4: Hus 1 | D4: 1 plans 100 kvm, 6 kW avgiven effekt | E4: 120 | F4: 1990 | G4: 55 | H4: =E4*G4 -> 6600 | J4: =H4/100*T$33 -> 4597.8625 | K4: =H4/100*T$33*K$2 -> 1195.4443 | L4: =H4/100*V$33 -> 3189.5875 | M4: =H4/100*V$33*M$2 -> 797.39687 | O4: =$Y33*$Y$35*12*((60-$Y$36)/60) -> 690.66667 | P4: =$Y33*$Y$35*12*((60-$Y$37)/60) -> 897.86667 | R4: ok att ändra, testa
C5: Hus 2 | D5: 1-plan villa 150 kvm, 8 kW avgiven effekt | E5: 160 | F5: 2010 | G5: 55 | H5: =E5*G5 -> 8800 | J5: =H5/100*T$33 -> 6130.4833 | K5: =H5/100*T$33*K$2 -> 1593.9257 | L5: =H5/100*V$33 -> 4252.7833 | M5: =H5/100*V$33*M$2 -> 1063.1958 | O5: =Z33*Y$35*12*((60-Y$36)/60) -> 1022 | P5: =$Z33*$Y$35*12*((60-$Y$37)/60) -> 1328.6
C6: Hus 3 | D6: 1,5 plan villa 200 kvm, 10 kW avgiven effekt | E6: 210 | F6: 1960 | G6: 60 | H6: =E6*G6 -> 12600 | J6: =H6/100*T$33 -> 8777.7375 | K6: =H6/100*T$33*K$2 -> 2282.2118 | L6: =H6/100*V$33 -> 6089.2125 | M6: =H6/100*V$33*M$2 -> 1522.3031 | O6: =AA33*Y$35*12*((60-Y$36)/60) -> 1194.6667 | P6: =$AA33*$Y$35*12*((60-$Y$37)/60) -> 1553.0667
C7: Hus 4 | D7: 2-plan villa 250 kvm+, 14 kW avgiven effekt | E7: 250 | F7: 1970 | G7: 70 | H7: =E7*G7 -> 17500 | J7: =H7/100*T$33 -> 12191.302 | K7: =H7/100*T$33*K$2 -> 3169.7385 | L7: =H7/100*V$33 -> 8457.2396 | M7: =H7/100*V$33*M$2 -> 2114.3099 | O7: =AB33*Y$35*12*((60-Y$36)/60) -> 1712.6667 | P7: =$AB33*$Y$35*12*((60-$Y$37)/60) -> 2226.4667
B8: LV | C8: Hus 1 | E8: 120 | G8: 75 | H8: =E8*G8 -> 9000 | J8: =H8/100*T$33 -> 6269.8125 | K8: =H8/100*T$33*K$2 -> 1630.1513 | L8: =H8/100*V$33 -> 4349.4375 | M8: =H8/100*V$33*M$2 -> 1087.3594 | O8: =$AC33*$Y$35*12*((60-$Y$36)/60) -> 849.33333 | P8: =$AC33*$Y$35*12*((60-$Y$37)/60) -> 1104.1333
C9: Hus 2 | E9: 160 | G9: 70 | H9: =E9*G9 -> 11200 | J9: =H9/100*T$33 -> 7802.4333 | K9: =H9/100*T$33*K$2 -> 2028.6327 | L9: =H9/100*V$33 -> 5412.6333 | M9: =H9/100*V$33*M$2 -> 1353.1583 | O9: =$AD33*$Y$35*12*((60-$Y$36)/60) -> 1152.6667 | P9: =$AD33*$Y$35*12*((60-$Y$37)/60) -> 1498.4667
C10: Hus 3 | E10: 210 | G10: 85 | H10: =E10*G10 -> 17850 | J10: =H10/100*T$33 -> 12435.128 | K10: =H10/100*T$33*K$2 -> 3233.1333 | L10: =H10/100*V$33 -> 8626.3844 | M10: =H10/100*V$33*M$2 -> 2156.5961 | O10: =$AE33*$Y$35*12*((60-$Y$36)/60) -> 1409.3333 | P10: =$AE33*$Y$35*12*((60-$Y$37)/60) -> 1832.1333
C11: Hus 4 | E11: 250 | G11: 90 | H11: =E11*G11 -> 22500 | J11: =H11/100*T$33 -> 15674.531 | K11: =H11/100*T$33*K$2 -> 4075.3781 | L11: =H11/100*V$33 -> 10873.594 | M11: =H11/100*V$33*M$2 -> 2718.3984 | O11: =$AF33*$Y$35*12*((60-$Y$36)/60) -> 1731.3333 | P11: =$AF33*$Y$35*12*((60-$Y$37)/60) -> 2250.7333
B12: FL | C12: Hus 1 | E12: 120 | G12: 100 | H12: =E12*G12 -> 12000 | J12: =H12/100*T$33 -> 8359.75 | K12: =H12/100*T$33*K$2 -> 2173.535 | L12: =H12/100*V$33 -> 5799.25 | M12: =H12/100*V$33*M$2 -> 1449.8125 | O12: =$AG33*$Y$35*12*((60-$Y$36)/60) -> 919.33333 | P12: =$AG33*$Y$35*12*((60-$Y$37)/60) -> 1195.1333
C13: Hus 2 | E13: 160 | G13: 110 | H13: =E13*G13 -> 17600 | J13: =H13/100*T$33 -> 12260.967 | K13: =H13/100*T$33*K$2 -> 3187.8513 | L13: =H13/100*V$33 -> 8505.5667 | M13: =H13/100*V$33*M$2 -> 2126.3917 | O13: =$AH33*$Y$35*12*((60-$Y$36)/60) -> 1236.6667 | P13: =$AH33*$Y$35*12*((60-$Y$37)/60) -> 1607.6667
C14: Hus 3 | E14: 210 | G14: 120 | H14: =E14*G14 -> 25200 | J14: =H14/100*T$33 -> 17555.475 | K14: =H14/100*T$33*K$2 -> 4564.4235 | L14: =H14/100*V$33 -> 12178.425 | M14: =H14/100*V$33*M$2 -> 3044.6062 | O14: =$AI33*$Y$35*12*((60-$Y$36)/60) -> 1544.6667 | P14: =$AI33*$Y$35*12*((60-$Y$37)/60) -> 2008.0667
C15: Hus 4 | E15: 250 | G15: 130 | H15: =E15*G15 -> 32500 | J15: =H15/100*T$33 -> 22640.99 | K15: =H15/100*T$33*K$2 -> 5886.6573 | L15: =H15/100*V$33 -> 15706.302 | M15: =H15/100*V$33*M$2 -> 3926.5755 | O15: =$AG33*$Y$35*12*((60-$Y$36)/60) -> 919.33333 | P15: =$AJ33*$Y$35*12*((60-$Y$37)/60) -> 2845.2667
J17: Sol 2023 egenanvändning före/efter | L17: Sol 2024 energikostnad, besparing
J19: 0.3 | K19: 0.46 | L19: 0.3 | M19: 0.48 | R19: Elpriser tabell | S19: 2023 | U19: 2024 | X19: Effekttabell tariffer | Y19: MV tillgänglig effekt | AC19: LV tillgänglig effekt | AG19: FL tillgänglig effekt
B20: Sol | C20: SE1 | D20: 25 paneler med 400 Wp | E20: 25 | G20: 320 | H20: 8000 | J20: =H20*J$19*((T$35+T$37)*T$36)/100 -> 2339.733 | K20: =(H20*K$19*((T$35+T$37)*T$36)/100)-(H20*J$19*((T$35+T$37)*T$36)/100) -> 1247.8576 | L20: =H20*L$19*((V$35+V$37)*V$36)/100 -> 1867.998 | M20: =(H20*M$19*((V$35+V$37)*V$36)/100)-(H20*L$19*((V$35+V$37)*V$36)/100) -> 1120.7988 | S20: el, exkl moms | T20: el, inkl moms+påslag | U20: exkl moms | V20: inkl moms+påslag | Y20: Hus 1 | Z20: Hus 2 | AA20: Hus 3 | AB20: Hus 4 | AC20: Hus 1 | AD20: Hus 2 | AE20: Hus 3 | AF20: Hus 4 | AG20: Hus 1 | AH20: Hus 2 | AI20: Hus 3 | AJ20: Hus 4
J21: =H21*J$19*((T$35+T$37)*T$36)/100 -> 0 | K21: =(H21*K$19*((T$35+T$37)*T$36)/100)-(H21*J$19*((T$35+T$37)*T$36)/100) -> 0 | L21: =H21*L$19*((V$35+V$37)*V$36)/100 -> 0 | M21: =(H21*M$19*((V$35+V$37)*V$36)/100)-(H21*L$19*((V$35+V$37)*V$36)/100) -> 0 | R21: jan | S21: 70.38 | T21: =(S21+10)*1.25 -> 100.475 | U21: 61.08 | V21: =(U21+10)*1.25 -> 88.85 | X21: jan | Y21: 1.7 | Z21: 2.4 | AA21: 3 | AB21: 4.2 | AC21: 2.3 | AD21: 3 | AE21: 3.7 | AF21: 4.8 | AG21: 3 | AH21: 4 | AI21: 5.5 | AJ21: 8
J22: =H22*J$19*((T$35+T$37)*T$36)/100 -> 0 | K22: =(H22*K$19*((T$35+T$37)*T$36)/100)-(H22*J$19*((T$35+T$37)*T$36)/100) -> 0 | L22: =H22*L$19*((V$35+V$37)*V$36)/100 -> 0 | M22: =(H22*M$19*((V$35+V$37)*V$36)/100)-(H22*L$19*((V$35+V$37)*V$36)/100) -> 0 | R22: feb | S22: 52.03 | T22: =(S22+10)*1.25 -> 77.5375 | U22: 44.79 | V22: =(U22+10)*1.25 -> 68.4875 | X22: feb | Y22: 1.7 | Z22: 2.4 | AA22: 3 | AB22: 4.2 | AC22: 2.5 | AD22: 3 | AE22: 3.7 | AF22: 4.8 | AG22: 3 | AH22: 4 | AI22: 5.5 | AJ22: 8
J23: =H23*J$19*((T$35+T$37)*T$36)/100 -> 0 | K23: =(H23*K$19*((T$35+T$37)*T$36)/100)-(H23*J$19*((T$35+T$37)*T$36)/100) -> 0 | L23: =H23*L$19*((V$35+V$37)*V$36)/100 -> 0 | M23: =(H23*M$19*((V$35+V$37)*V$36)/100)-(H23*L$19*((V$35+V$37)*V$36)/100) -> 0 | R23: mar | S23: 56.49 | T23: =(S23+10)*1.25 -> 83.1125 | U23: 56.61 | V23: =(U23+10)*1.25 -> 83.2625 | X23: mar | Y23: 1.6 | Z23: 2.3 | AA23: 2.6 | AB23: 3.8 | AC23: 2 | AD23: 2.7 | AE23: 3.2 | AF23: 4 | AG23: 2.5 | AH23: 3.8 | AI23: 4.4 | AJ23: 6.5
R24: apr | S24: 66.47 | T24: =(S24+10)*1.25 -> 95.5875 | U24: 50.47 | V24: =(U24+10)*1.25 -> 75.5875 | X24: apr | Y24: 1.5 | Z24: 2 | AA24: 2.4 | AB24: 3.5 | AC24: 1.8 | AD24: 2.2 | AE24: 3 | AF24: 3.5 | AG24: 2 | AH24: 2.8 | AI24: 3 | AJ24: 4
J25: SE 1 Sammanfattning | O25: 2023 | R25: maj | S25: 27.77 | T25: =(S25+10)*1.25 -> 47.2125 | U25: 17.64 | V25: =(U25+10)*1.25 -> 34.55 | X25: maj | Y25: 1 | Z25: 1.5 | AA25: 1.8 | AB25: 2.5 | AC25: 1.2 | AD25: 1.5 | AE25: 2 | AF25: 2.4 | AG25: 0.8 | AH25: 1 | AI25: 1 | AJ25: 1.5
B26: Elbil | C26: SE1-4 | D26: 1500 mil á 2 kr/kWh, 70% hemma | E26: 1500 | F26: 0.7 | G26: 2 | H26: =E26*G26*F26 -> 2100 | K26: BV | L26: hus 1 | M26: nej | O26: =K4+O4 -> 1886.1109 | R26: jun | S26: 51.61 | T26: =(S26+10)*1.25 -> 77.0125 | U26: 24.04 | V26: =(U26+10)*1.25 -> 42.55 | X26: jun | Y26: 0.8 | Z26: 1.2 | AA26: 1.5 | AB26: 2 | AC26: 0.8 | AD26: 1.2 | AE26: 1.5 | AF26: 1.8 | AG26: 0.6 | AH26: 0.6 | AI26: 0.6 | AJ26: 0.6
M27: sol | O27: =O26+K$20 -> 3133.9685 | R27: jul | S27: 37.4 | T27: =(S27+10)*1.25 -> 59.25 | U27: 20.55 | V27: =(U27+10)*1.25 -> 38.1875 | X27: jul | Y27: 0.8 | Z27: 1.2 | AA27: 1.5 | AB27: 2 | AC27: 0.8 | AD27: 1.2 | AE27: 1.5 | AF27: 1.8 | AG27: 0.6 | AH27: 0.6 | AI27: 0.6 | AJ27: 0.6
M28: elbil | O28: =K4+P4 -> 2093.3109 | R28: aug | S28: 23.76 | T28: =(S28+10)*1.25 -> 42.2 | U28: 8.86 | V28: =(U28+10)*1.25 -> 23.575 | X28: aug | Y28: 0.8 | Z28: 1.2 | AA28: 1.5 | AB28: 2 | AC28: 0.8 | AD28: 1.2 | AE28: 1.5 | AF28: 1.8 | AG28: 0.6 | AH28: 0.6 | AI28: 0.6 | AJ28: 0.6
M29: sol+elbil | O29: =O28+K$20 -> 3341.1685 | R29: sep | S29: 10.89 | T29: =(S29+10)*1.25 -> 26.1125 | U29: 9.57 | V29: =(U29+10)*1.25 -> 24.4625 | X29: sep | Y29: 0.8 | Z29: 1.2 | AA29: 1.5 | AB29: 2 | AC29: 0.8 | AD29: 1.2 | AE29: 1.5 | AF29: 1.8 | AG29: 0.6 | AH29: 0.6 | AI29: 0.6 | AJ29: 0.6
L30: hus 2 | M30: nej | O30: =K5+O5 -> 2615.9257 | R30: okt | S30: 17.58 | T30: =(S30+10)*1.25 -> 34.475 | U30: 12.6 | V30: =(U30+10)*1.25 -> 28.25 | X30: okt | Y30: 1 | Z30: 2 | AA30: 1.8 | AB30: 3 | AC30: 1 | AD30: 2 | AE30: 2 | AF30: 2.4 | AG30: 1 | AH30: 1.5 | AI30: 2 | AJ30: 3
M31: sol | O31: =O30+K$20 -> 3863.7833 | R31: nov | S31: 60.9 | T31: =(S31+10)*1.25 -> 88.625 | U31: 24.96 | V31: =(U31+10)*1.25 -> 43.7 | X31: nov | Y31: 1.5 | Z31: 2.2 | AA31: 2.4 | AB31: 3.5 | AC31: 2 | AD31: 2.5 | AE31: 3 | AF31: 3.5 | AG31: 2 | AH31: 3 | AI31: 3.8 | AJ31: 6
M32: elbil | O32: =K5+P5 -> 2922.5257 | R32: dec | S32: 73.5 | T32: =(S32+10)*1.25 -> 104.375 | U32: 12.77 | V32: =(U32+10)*1.25 -> 28.4625 | X32: dec | Y32: 1.6 | Z32: 2.3 | AA32: 2.6 | AB32: 4 | AC32: 2.2 | AD32: 3 | AE32: 3.6 | AF32: 4.5 | AG32: 3 | AH32: 4 | AI32: 5.5 | AJ32: 7.5
M33: sol+elbil | O33: =O32+K$20 -> 4170.3833 | R33: Medel: | S33: =SUM(S21:S32)/12 -> 45.731667 | T33: =SUM(T21:T32)/12 -> 69.664583 | U33: =SUM(U21:U32)/12 -> 28.661667 | V33: =SUM(V21:V32)/12 -> 48.327083 | X33: Medel: | Y33: 1.2333333 | Z33: 1.825 | AA33: 2.1333333 | AB33: 3.0583333 | AC33: 1.5166667 | AD33: 2.0583333 | AE33: 2.5166667 | AF33: 3.0916667 | AG33: 1.6416667 | AH33: 2.2083333 | AI33: 2.7583333 | AJ33: 3.9083333
L34: hus 3 | M34: nej | O34: =K6+O6 -> 3476.8784 | X34: VP avgiven effekt: | Y34: 6 | Z34: 8 | AA34: 10 | AB34: 14 | AC34: 6 | AD34: 8 | AE34: 10 | AF34: 14 | AG34: 6 | AH34: 8 | AI34: 10 | AJ34: 14
M35: sol | O35: =O34+K$20 -> 4724.736 | R35: Medel solel: | S35: (juni-sept) | T35: =SUM(T25:T30)/6 -> 47.710417 | V35: =SUM(V25:V30)/6 -> 31.929167 | X35: Tariffpris: | Y35: 70
M36: elbil | O36: =K6+P6 -> 3835.2784 | R36: Sol-elpris: | T36: 0.66 | V36: 0.66 | X36: Reaktionstid, min: | Y36: 20
M37: sol+elbil | O37: =O36+K$20 -> 5083.136 | R37: Elöverf/skatt: | T37: 100 | V37: 86 | X37: Reak-tid inkl elbil, min: | Y37: 8
L38: hus 4 | M38: nej | O38: =K7+O7 -> 4882.4052
M39: sol | O39: =O38+K$20 -> 6130.2628
M40: elbil | O40: =K7+P7 -> 5396.2052
M41: sol+elbil | O41: =O40+K$20 -> 6644.0628
K42: LV | L42: hus 1 | M42: nej | O42: =K8+O8 -> 2479.4846
...

Sheet Elpriser
B1: SE3 | C1: SE3 | D1: SE2 | E1: SE1 | G1: SE1 | H1: 2023 | I1: 2024 | J1: 2025
A2: 44927 | B2: 104.43 | C2: 92.58 | D2: 70.38 | E2: 70.38 | G2: jan | H2: 82.11 | I2: 78.92 | J2: 37.89
A3: Februari | B3: 102.79 | C3: 82.54 | D3: 52.03 | E3: 52.03 | G3: feb | H3: 63.44 | I3: 60.86 | J3: 25.74
A4: Mars | B4: 91.79 | C4: 80.62 | D4: 56.49 | E4: 56.49 | G4: mar | H4: 66.79 | I4: 69.73 | J4: 29.20
A5: April | B5: 73.87 | C5: 68.7 | D5: 66.47 | E5: 66.47 | G5: apr | H5: 76.33 | I5: 63.25 | J5: 27.44
A6: Maj | B6: 73.5 | C6: 39.02 | D6: 27.84 | E6: 27.77 | G6: maj | H6: 40.85 | I6: 31.77 | J6: 27.92
A7: Juni | B7: 103.39 | C7: 53.06 | D7: 51.61 | E7: 51.61 | G7: jun | H7: 59.42 | I7: 36.40 | J7: 15.60
A8: Juli | B8: 41.76 | C8: 37.65 | D8: 37.4 | E8: 37.4 | G8: jul | H8: 47.93 | I8: 32.13 | J8: 26.95
A9: Augusti | B9: 49.54 | C9: 36.96 | D9: 23.76 | E9: 23.76 | G9: aug | H9: 34.66 | I9: 20.23 | J9: 38.61
A10: September | B10: 51.33 | C10: 24.32 | D10: 10.89 | E10: 10.89 | G10: sep | H10: 21.91 | I10: 21.41 | J10: 30.52
A11: Oktober | B11: 35.95 | C11: 33.06 | D11: 17.58 | E11: 17.58 | G11: okt | H11: 32.33 | I11: 23.92 | J11: -
A12: November | B12: 84.72 | C12: 82.13 | D12: 60.9 | E12: 60.9 | G12: nov | H12: 76.85 | I12: 37.65 | J12: -
A13: December | B13: 81.39 | C13: 80.29 | D13: 73.5 | E13: 73.5 | G13: dec | H13: 87.72 | I13: 24.84 | J13: -
A14: 45292 | B14: 84.02 | C14: 80.3 | D14: 61.2 | E14: 61.08
A15: Februari | B15: 55.42 | C15: 50.34 | D15: 44.94 | E15: 44.79 | G15: SE2 | H15: 2023 | I15: 2024 | J15: 2025
A16: Mars | B16: 63.36 | C16: 59.47 | D16: 56.61 | E16: 56.61 | G16: jan | H16: 82.39 | I16: 79.74 | J16: 37.49
A17: April | B17: 62.45 | C17: 56.31 | D17: 50.79 | E17: 50.47 | G17: feb | H17: 63.90 | I17: 60.89 | J17: 27.49
A18: Maj | B18: 50.58 | C18: 23.71 | D18: 17.64 | E18: 17.64 | G18: mar | H18: 67.42 | I18: 69.91 | J18: 24.16
A19: Juni | B19: 62.7 | C19: 27.27 | D19: 24.04 | E19: 24.04 | G19: apr | H19: 76.13 | I19: 64.11 | J19: 27.31
A20: Juli | B20: 43.34 | C20: 20.72 | D20: 20.49 | E20: 20.55 | G20: maj | H20: 41.58 | I20: 31.92 | J20: 29.16
A21: Augusti | B21: 45.93 | C21: 8.54 | D21: 8.51 | E21: 8.86 | G21: jun | H21: 59.29 | I21: 36.37 | J21: 19.85
A22: September | B22: 30.67 | C22: 16.44 | D22: 10.89 | E22: 9.57 | G22: jul | H22: 47.95 | I22: 31.99 | J22: 29.15
A23: Oktober | B23: 30.15 | C23: 22.97 | D23: 13.52 | E23: 12.6 | G23: aug | H23: 34.66 | I23: 19.84 | J23: 37.62
A24: November | B24: 84.65 | C24: 66.95 | D24: 18.09 | E24: 24.96 | G24: sep | H24: 22.00 | I24: 22.73 | J24: 29.47
A25: December | B25: 70.77 | C25: 59.57 | D25: 11.35 | E25: 12.77 | G25: okt | H25: 32.35 | I25: 24.73 | J25: -
G26: nov | H26: 78.07 | I26: 31.02 | J26: -
G27: dec | H27: 89.69 | I27: 23.34 | J27: -

Sheet Används ej
B3: Ändra här för hela dokumentet | C3: SE4 | D3: SE3 | E3: SE2 | F3: SE1
A4: SPO | B4: Lägre elpris, timpris genomsnitt (%)
A5: SOL
A6: Tariff
